Workbook

Sheet ADD_evt
I1: 2023 | L1: 2015
A2: id | B2: class | C2: tract_id | D2: stratum | E2: lon | F2: lat | G2: gsv_link | H2: GSV | I2: present_2023 | J2: present_2024 | K2: present_2022 | L2: present_2015 | M2: present_2014 | N2: present_2016 | O2: notes | P2: present_followup | Q2: present_baseline | R2: Match
A3: 1 | B3: ADD | C3: tract_0001 | D3: D1_C1 | E3: 2.1121109 | F3: 41.390968 | G3: https://www.google.com/maps/@?api=1&map_action=pano&viewpoint=41.3909679997347,2.11211089874738 | H3: =HYPERLINK("https://www.google.com/maps/@?api=1&map_action=pano&viewpoint=41.3909679997347,2.11211089874738","Open GSV") -> Open GSV | I3: NA | J3: NA | K3: 1 | L3: 0 | O3: Peg moved 23 | P3: =IF(OR(I3=1,I3="1",I3=0,I3="0"),I3,IF(OR(J3=1,J3="1",J3=0,J3="0"),J3,IF(OR(K3=1,K3="1",K3=0,K3="0"),K3,"NA"))) -> 1 | Q3: =IF(OR(L3=1,L3="1",L3=0,L3="0"),L3,IF(OR(M3=1,M3="1",M3=0,M3="0"),M3,IF(OR(N3=1,N3="1",N3=0,N3="0"),N3,"NA"))) -> 0 | R3: =AND(ROUND(P3,0)=1, ROUND(Q3,0)=0) -> TRUE
A4: 2 | B4: ADD | C4: tract_0003 | D4: D1_C1 | E4: 2.1803101 | F4: 41.458146 | G4: https://www.google.com/maps/@?api=1&map_action=pano&viewpoint=41.4581456267453,2.18031012416 | H4: =HYPERLINK("https://www.google.com/maps/@?api=1&map_action=pano&viewpoint=41.4581456267453,2.18031012416","Open GSV") -> Open GSV | I4: 1 | L4: NA | M4: 1 | O4: Peg moved 15; present 11 | P4: =IF(OR(I4=1,I4="1",I4=0,I4="0"),I4,IF(OR(J4=1,J4="1",J4=0,J4="0"),J4,IF(OR(K4=1,K4="1",K4=0,K4="0"),K4,"NA"))) -> 1 | Q4: =IF(OR(L4=1,L4="1",L4=0,L4="0"),L4,IF(OR(M4=1,M4="1",M4=0,M4="0"),M4,IF(OR(N4=1,N4="1",N4=0,N4="0"),N4,"NA"))) -> 1 | R4: =AND(ROUND(P4,0)=1, ROUND(Q4,0)=0) -> FALSE
A5: 3 | B5: ADD | C5: tract_0004 | D5: D1_C1 | E5: 2.1408527 | F5: 41.413422 | G5: https://www.google.com/maps/@?api=1&map_action=pano&viewpoint=41.4134215995416,2.14085269668676 | H5: =HYPERLINK("https://www.google.com/maps/@?api=1&map_action=pano&viewpoint=41.4134215995416,2.14085269668676","Open GSV") -> Open GSV | I5: NA | J5: 1 | L5: 0 | O5: Peg moved 23 | P5: =IF(OR(I5=1,I5="1",I5=0,I5="0"),I5,IF(OR(J5=1,J5="1",J5=0,J5="0"),J5,IF(OR(K5=1,K5="1",K5=0,K5="0"),K5,"NA"))) -> 1 | Q5: =IF(OR(L5=1,L5="1",L5=0,L5="0"),L5,IF(OR(M5=1,M5="1",M5=0,M5="0"),M5,IF(OR(N5=1,N5="1",N5=0,N5="0"),N5,"NA"))) -> 0 | R5: =AND(ROUND(P5,0)=1, ROUND(Q5,0)=0) -> TRUE
A6: 4 | B6: ADD | C6: tract_0006 | D6: D1_C1 | E6: 2.2011317 | F6: 41.426283 | G6: https://www.google.com/maps/@?api=1&map_action=pano&viewpoint=41.4262832087554,2.20113165987653 | H6: =HYPERLINK("https://www.google.com/maps/@?api=1&map_action=pano&viewpoint=41.4262832087554,2.20113165987653","Open GSV") -> Open GSV | I6: 1 | L6: 0 | P6: =IF(OR(I6=1,I6="1",I6=0,I6="0"),I6,IF(OR(J6=1,J6="1",J6=0,J6="0"),J6,IF(OR(K6=1,K6="1",K6=0,K6="0"),K6,"NA"))) -> 1 | Q6: =IF(OR(L6=1,L6="1",L6=0,L6="0"),L6,IF(OR(M6=1,M6="1",M6=0,M6="0"),M6,IF(OR(N6=1,N6="1",N6=0,N6="0"),N6,"NA"))) -> 0 | R6: =AND(ROUND(P6,0)=1, ROUND(Q6,0)=0) -> TRUE
A7: 5 | B7: ADD | C7: tract_0006 | D7: D1_C1 | E7: 2.2001191 | F7: 41.426033 | G7: https://www.google.com/maps/@?api=1&map_action=pano&viewpoint=41.4260327049088,2.2001190522901 | H7: =HYPERLINK("https://www.google.com/maps/@?api=1&map_action=pano&viewpoint=41.4260327049088,2.2001190522901","Open GSV") -> Open GSV | I7: 1 | L7: 0 | P7: =IF(OR(I7=1,I7="1",I7=0,I7="0"),I7,IF(OR(J7=1,J7="1",J7=0,J7="0"),J7,IF(OR(K7=1,K7="1",K7=0,K7="0"),K7,"NA"))) -> 1 | Q7: =IF(OR(L7=1,L7="1",L7=0,L7="0"),L7,IF(OR(M7=1,M7="1",M7=0,M7="0"),M7,IF(OR(N7=1,N7="1",N7=0,N7="0"),N7,"NA"))) -> 0 | R7: =AND(ROUND(P7,0)=1, ROUND(Q7,0)=0) -> TRUE
A8: 6 | B8: ADD | C8: tract_0007 | D8: D1_C2 | E8: 2.1347574 | F8: 41.389964 | G8: https://www.google.com/maps/@?api=1&map_action=pano&viewpoint=41.3899636143591,2.134757401236 | H8: =HYPERLINK("https://www.google.com/maps/@?api=1&map_action=pano&viewpoint=41.3899636143591,2.134757401236","Open GSV") -> Open GSV | I8: NA | J8: 0 | L8: 0 | O8: Peg moved 23 | P8: =IF(OR(I8=1,I8="1",I8=0,I8="0"),I8,IF(OR(J8=1,J8="1",J8=0,J8="0"),J8,IF(OR(K8=1,K8="1",K8=0,K8="0"),K8,"NA"))) -> 0 | Q8: =IF(OR(L8=1,L8="1",L8=0,L8="0"),L8,IF(OR(M8=1,M8="1",M8=0,M8="0"),M8,IF(OR(N8=1,N8="1",N8=0,N8="0"),N8,"NA"))) -> 0 | R8: =AND(ROUND(P8,0)=1, ROUND(Q8,0)=0) -> FALSE
A9: 7 | B9: ADD | C9: tract_0007 | D9: D1_C2 | E9: 2.1340276 | F9: 41.388185 | G9: https://www.google.com/maps/@?api=1&map_action=pano&viewpoint=41.3881854073843,2.13402755812854 | H9: =HYPERLINK("https://www.google.com/maps/@?api=1&map_action=pano&viewpoint=41.3881854073843,2.13402755812854","Open GSV") -> Open GSV | I9: NA | J9: NA | K9: 1 | L9: 0 | P9: =IF(OR(I9=1,I9="1",I9=0,I9="0"),I9,IF(OR(J9=1,J9="1",J9=0,J9="0"),J9,IF(OR(K9=1,K9="1",K9=0,K9="0"),K9,"NA"))) -> 1 | Q9: =IF(OR(L9=1,L9="1",L9=0,L9="0"),L9,IF(OR(M9=1,M9="1",M9=0,M9="0"),M9,IF(OR(N9=1,N9="1",N9=0,N9="0"),N9,"NA"))) -> 0 | R9: =AND(ROUND(P9,0)=1, ROUND(Q9,0)=0) -> TRUE
A10: 8 | B10: ADD | C10: tract_0009 | D10: D1_C2 | E10: 2.1988167 | F10: 41.416812 | G10: https://www.google.com/maps/@?api=1&map_action=pano&viewpoint=41.4168121764961,2.19881673887713 | H10: =HYPERLINK("https://www.google.com/maps/@?api=1&map_action=pano&viewpoint=41.4168121764961,2.19881673887713","Open GSV") -> Open GSV | I10: 1 | L10: NA | M10: 0 | P10: =IF(OR(I10=1,I10="1",I10=0,I10="0"),I10,IF(OR(J10=1,J10="1",J10=0,J10="0"),J10,IF(OR(K10=1,K10="1",K10=0,K10="0"),K10,"NA"))) -> 1 | Q10: =IF(OR(L10=1,L10="1",L10=0,L10="0"),L10,IF(OR(M10=1,M10="1",M10=0,M10="0"),M10,IF(OR(N10=1,N10="1",N10=0,N10="0"),N10,"NA"))) -> 0 | R10: =AND(ROUND(P10,0)=1, ROUND(Q10,0)=0) -> TRUE
A11: 9 | B11: ADD | C11: tract_0010 | D11: D1_C2 | E11: 2.1746102 | F11: 41.416865 | G11: https://www.google.com/maps/@?api=1&map_action=pano&viewpoint=41.4168653577514,2.17461017557639 | H11: =HYPERLINK("https://www.google.com/maps/@?api=1&map_action=pano&viewpoint=41.4168653577514,2.17461017557639","Open GSV") -> Open GSV | I11: 1 | L11: 0 | O11: Peg moved 23 | P11: =IF(OR(I11=1,I11="1",I11=0,I11="0"),I11,IF(OR(J11=1,J11="1",J11=0,J11="0"),J11,IF(OR(K11=1,K11="1",K11=0,K11="0"),K11,"NA"))) -> 1 | Q11: =IF(OR(L11=1,L11="1",L11=0,L11="0"),L11,IF(OR(M11=1,M11="1",M11=0,M11="0"),M11,IF(OR(N11=1,N11="1",N11=0,N11="0"),N11,"NA"))) -> 0 | R11: =AND(ROUND(P11,0)=1, ROUND(Q11,0)=0) -> TRUE
A12: 10 | B12: ADD | C12: tract_0010 | D12: D1_C2 | E12: 2.172051 | F12: 41.414976 | G12: https://www.google.com/maps/@?api=1&map_action=pano&viewpoint=41.414975730964,2.17205102853822 | H12: =HYPERLINK("https://www.google.com/maps/@?api=1&map_action=pano&viewpoint=41.414975730964,2.17205102853822","Open GSV") -> Open GSV | I12: NA | J12: NA | K12: NA | L12: NA | M12: NA | N12: NA | O12: Realigment | P12: =IF(OR(I12=1,I12="1",I12=0,I12="0"),I12,IF(OR(J12=1,J12="1",J12=0,J12="0"),J12,IF(OR(K12=1,K12="1",K12=0,K12="0"),K12,"NA"))) -> NA | Q12: =IF(OR(L12=1,L12="1",L12=0,L12="0"),L12,IF(OR(M12=1,M12="1",M12=0,M12="0"),M12,IF(OR(N12=1,N12="1",N12=0,N12="0"),N12,"NA"))) -> NA | R12: =AND(ROUND(P12,0)=1, ROUND(Q12,0)=0) -> #VALUE!
A13: 11 | B13: ADD | C13: tract_0011 | D13: D1_C2 | E13: 2.2075546 | F13: 41.420448 | G13: https://www.google.com/maps/@?api=1&map_action=pano&viewpoint=41.4204481302083,2.2075546110796 | H13: =HYPERLINK("https://www.google.com/maps/@?api=1&map_action=pano&viewpoint=41.4204481302083,2.2075546110796","Open GSV") -> Open GSV | I13: 1 | L13: NA | M13: 1 | O13: Peg moved 23 | P13: =IF(OR(I13=1,I13="1",I13=0,I13="0"),I13,IF(OR(J13=1,J13="1",J13=0,J13="0"),J13,IF(OR(K13=1,K13="1",K13=0,K13="0"),K13,"NA"))) -> 1 | Q13: =IF(OR(L13=1,L13="1",L13=0,L13="0"),L13,IF(OR(M13=1,M13="1",M13=0,M13="0"),M13,IF(OR(N13=1,N13="1",N13=0,N13="0"),N13,"NA"))) -> 1 | R13: =AND(ROUND(P13,0)=1, ROUND(Q13,0)=0) -> FALSE
A14: 12 | B14: ADD | C14: tract_0011 | D14: D1_C2 | E14: 2.2079426 | F14: 41.420245 | G14: https://www.google.com/maps/@?api=1&map_action=pano&viewpoint=41.4202454258576,2.20794256929774 | H14: =HYPERLINK("https://www.google.com/maps/@?api=1&map_action=pano&viewpoint=41.4202454258576,2.20794256929774","Open GSV") -> Open GSV | I14: 1 | L14: NA | M14: 1 | O14: Peg moved 23 | P14: =IF(OR(I14=1,I14="1",I14=0,I14="0"),I14,IF(OR(J14=1,J14="1",J14=0,J14="0"),J14,IF(OR(K14=1,K14="1",K14=0,K14="0"),K14,"NA"))) -> 1 | Q14: =IF(OR(L14=1,L14="1",L14=0,L14="0"),L14,IF(OR(M14=1,M14="1",M14=0,M14="0"),M14,IF(OR(N14=1,N14="1",N14=0,N14="0"),N14,"NA"))) -> 1 | R14: =AND(ROUND(P14,0)=1, ROUND(Q14,0)=0) -> FALSE
A15: 13 | B15: ADD | C15: tract_0012 | D15: D1_C2 | E15: 2.1609809 | F15: 41.412109 | G15: https://www.google.com/maps/@?api=1&map_action=pano&viewpoint=41.4121092794043,2.16098092184219 | H15: =HYPERLINK("https://www.google.com/maps/@?api=1&map_action=pano&viewpoint=41.4121092794043,2.16098092184219","Open GSV") -> Open GSV | I15: 1 | L15: 0 | P15: =IF(OR(I15=1,I15="1",I15=0,I15="0"),I15,IF(OR(J15=1,J15="1",J15=0,J15="0"),J15,IF(OR(K15=1,K15="1",K15=0,K15="0"),K15,"NA"))) -> 1 | Q15: =IF(OR(L15=1,L15="1",L15=0,L15="0"),L15,IF(OR(M15=1,M15="1",M15=0,M15="0"),M15,IF(OR(N15=1,N15="1",N15=0,N15="0"),N15,"NA"))) -> 0 | R15: =AND(ROUND(P15,0)=1, ROUND(Q15,0)=0) -> TRUE
A16: 14 | B16: ADD | C16: tract_0012 | D16: D1_C2 | E16: 2.1617583 | F16: 41.412547 | G16: https://www.google.com/maps/@?api=1&map_action=pano&viewpoint=41.4125465819168,2.16175831110785 | H16: =HYPERLINK("https://www.google.com/maps/@?api=1&map_action=pano&viewpoint=41.4125465819168,2.16175831110785","Open GSV") -> Open GSV | I16: 1 | L16: 0 | O16: Peg moved both | P16: =IF(OR(I16=1,I16="1",I16=0,I16="0"),I16,IF(OR(J16=1,J16="1",J16=0,J16="0"),J16,IF(OR(K16=1,K16="1",K16=0,K16="0"),K16,"NA"))) -> 1 | Q16: =IF(OR(L16=1,L16="1",L16=0,L16="0"),L16,IF(OR(M16=1,M16="1",M16=0,M16="0"),M16,IF(OR(N16=1,N16="1",N16=0,N16="0"),N16,"NA"))) -> 0 | R16: =AND(ROUND(P16,0)=1, ROUND(Q16,0)=0) -> TRUE
A17: 15 | B17: ADD | C17: tract_0013 | D17: D1_C3 | E17: 2.2007726 | F17: 41.394521 | G17: https://www.google.com/maps/@?api=1&map_action=pano&viewpoint=41.3945206907087,2.20077256303846 | H17: =HYPERLINK("https://www.google.com/maps/@?api=1&map_action=pano&viewpoint=41.3945206907087,2.20077256303846","Open GSV") -> Open GSV | I17: NA | J17: 1 | L17: 0 | P17: =IF(OR(I17=1,I17="1",I17=0,I17="0"),I17,IF(OR(J17=1,J17="1",J17=0,J17="0"),J17,IF(OR(K17=1,K17="1",K17=0,K17="0"),K17,"NA"))) -> 1 | Q17: =IF(OR(L17=1,L17="1",L17=0,L17="0"),L17,IF(OR(M17=1,M17="1",M17=0,M17="0"),M17,IF(OR(N17=1,N17="1",N17=0,N17="0"),N17,"NA"))) -> 0 | R17: =AND(ROUND(P17,0)=1, ROUND(Q17,0)=0) -> TRUE
A18: 16 | B18: ADD | C18: tract_0013 | D18: D1_C3 | E18: 2.2010092 | F18: 41.394719 | G18: https://www.google.com/maps/@?api=1&map_action=pano&viewpoint=41.394718915396,2.20100922656311 | H18: =HYPERLINK("https://www.google.com/maps/@?api=1&map_action=pano&viewpoint=41.394718915396,2.20100922656311","Open GSV") -> Open GSV | I18: 1 | L18: 0 | P18: =IF(OR(I18=1,I18="1",I18=0,I18="0"),I18,IF(OR(J18=1,J18="1",J18=0,J18="0"),J18,IF(OR(K18=1,K18="1",K18=0,K18="0"),K18,"NA"))) -> 1 | Q18: =IF(OR(L18=1,L18="1",L18=0,L18="0"),L18,IF(OR(M18=1,M18="1",M18=0,M18="0"),M18,IF(OR(N18=1,N18="1",N18=0,N18="0"),N18,"NA"))) -> 0 | R18: =AND(ROUND(P18,0)=1, ROUND(Q18,0)=0) -> TRUE
A19: 17 | B19: ADD | C19: tract_0017 | D19: D1_C3 | E19: 2.1451506 | F19: 41.376224 | G19: https://www.google.com/maps/@?api=1&map_action=pano&viewpoint=41.3762241357195,2.14515055931621 | H19: =HYPERLINK("https://www.google.com/maps/@?api=1&map_action=pano&viewpoint=41.3762241357195,2.14515055931621","Open GSV") -> Open GSV | I19: 1 | L19: 0 | P19: =IF(OR(I19=1,I19="1",I19=0,I19="0"),I19,IF(OR(J19=1,J19="1",J19=0,J19="0"),J19,IF(OR(K19=1,K19="1",K19=0,K19="0"),K19,"NA"))) -> 1 | Q19: =IF(OR(L19=1,L19="1",L19=0,L19="0"),L19,IF(OR(M19=1,M19="1",M19=0,M19="0"),M19,IF(OR(N19=1,N19="1",N19=0,N19="0"),N19,"NA"))) -> 0 | R19: =AND(ROUND(P19,0)=1, ROUND(Q19,0)=0) -> TRUE
A20: 18 | B20: ADD | C20: tract_0017 | D20: D1_C3 | E20: 2.1455917 | F20: 41.376413 | G20: https://www.google.com/maps/@?api=1&map_action=pano&viewpoint=41.3764134914288,2.14559167922172 | H20: =HYPERLINK("https://www.google.com/maps/@?api=1&map_action=pano&viewpoint=41.3764134914288,2.14559167922172","Open GSV") -> Open GSV | I20: 1 | L20: 0 | P20: =IF(OR(I20=1,I20="1",I20=0,I20="0"),I20,IF(OR(J20=1,J20="1",J20=0,J20="0"),J20,IF(OR(K20=1,K20="1",K20=0,K20="0"),K20,"NA"))) -> 1 | Q20: =IF(OR(L20=1,L20="1",L20=0,L20="0"),L20,IF(OR(M20=1,M20="1",M20=0,M20="0"),M20,IF(OR(N20=1,N20="1",N20=0,N20="0"),N20,"NA"))) -> 0 | R20: =AND(ROUND(P20,0)=1, ROUND(Q20,0)=0) -> TRUE
A21: 19 | B21: ADD | C21: tract_0018 | D21: D1_C3 | E21: 2.1828475 | F21: 41.405575 | G21: https://www.google.com/maps/@?api=1&map_action=pano&viewpoint=41.4055753756871,2.18284748138898 | H21: =HYPERLINK("https://www.google.com/maps/@?api=1&map_action=pano&viewpoint=41.4055753756871,2.18284748138898","Open GSV") -> Open GSV | I21: 1 | L21: 0 | P21: =IF(OR(I21=1,I21="1",I21=0,I21="0"),I21,IF(OR(J21=1,J21="1",J21=0,J21="0"),J21,IF(OR(K21=1,K21="1",K21=0,K21="0"),K21,"NA"))) -> 1 | Q21: =IF(OR(L21=1,L21="1",L21=0,L21="0"),L21,IF(OR(M21=1,M21="1",M21=0,M21="0"),M21,IF(OR(N21=1,N21="1",N21=0,N21="0"),N21,"NA"))) -> 0 | R21: =AND(ROUND(P21,0)=1, ROUND(Q21,0)=0) -> TRUE
A22: 20 | B22: ADD | C22: tract_0018 | D22: D1_C3 | E22: 2.1828597 | F22: 41.403095 | G22: https://www.google.com/maps/@?api=1&map_action=pano&viewpoint=41.403094880684,2.18285971742863 | H22: =HYPERLINK("https://www.google.com/maps/@?api=1&map_action=pano&viewpoint=41.403094880684,2.18285971742863","Open GSV") -> Open GSV | I22: 1 | L22: 0 | P22: =IF(OR(I22=1,I22="1",I22=0,I22="0"),I22,IF(OR(J22=1,J22="1",J22=0,J22="0"),J22,IF(OR(K22=1,K22="1",K22=0,K22="0"),K22,"NA"))) -> 1 | Q22: =IF(OR(L22=1,L22="1",L22=0,L22="0"),L22,IF(OR(M22=1,M22="1",M22=0,M22="0"),M22,IF(OR(N22=1,N22="1",N22=0,N22="0"),N22,"NA"))) -> 0 | R22: =AND(ROUND(P22,0)=1, ROUND(Q22,0)=0) -> TRUE
A23: 21 | B23: ADD | C23: tract_0023 | D23: D2_C1 | E23: 2.1758556 | F23: 41.428756 | G23: https://www.google.com/maps/@?api=1&map_action=pano&viewpoint=41.4287555466715,2.17585558557915 | H23: =HYPERLINK("https://www.google.com/maps/@?api=1&map_action=pano&viewpoint=41.4287555466715,2.17585558557915","Open GSV") -> Open GSV | I23: 1 | L23: NA | M23: 1 | P23: =IF(OR(I23=1,I23="1",I23=0,I23="0"),I23,IF(OR(J23=1,J23="1",J23=0,J23="0"),J23,IF(OR(K23=1,K23="1",K23=0,K23="0"),K23,"NA"))) -> 1 | Q23: =IF(OR(L23=1,L23="1",L23=0,L23="0"),L23,IF(OR(M23=1,M23="1",M23=0,M23="0"),M23,IF(OR(N23=1,N23="1",N23=0,N23="0"),N23,"NA"))) -> 1 | R23: =AND(ROUND(P23,0)=1, ROUND(Q23,0)=0) -> FALSE
A24: 22 | B24: ADD | C24: tract_0024 | D24: D2_C1 | E24: 2.1908314 | F24: 41.440995 | G24: https://www.google.com/maps/@?api=1&map_action=pano&viewpoint=41.4409954760919,2.19083141351904 | H24: =HYPERLINK("https://www.google.com/maps/@?api=1&map_action=pano&viewpoint=41.4409954760919,2.19083141351904","Open GSV") -> Open GSV | I24: 1 | L24: NA | M24: 1 | P24: =IF(OR(I24=1,I24="1",I24=0,I24="0"),I24,IF(OR(J24=1,J24="1",J24=0,J24="0"),J24,IF(OR(K24=1,K24="1",K24=0,K24="0"),K24,"NA"))) -> 1 | Q24: =IF(OR(L24=1,L24="1",L24=0,L24="0"),L24,IF(OR(M24=1,M24="1",M24=0,M24="0"),M24,IF(OR(N24=1,N24="1",N24=0,N24="0"),N24,"NA"))) -> 1 | R24: =AND(ROUND(P24,0)=1, ROUND(Q24,0)=0) -> FALSE
A25: 23 | B25: ADD | C25: tract_0025 | D25: D2_C2 | E25: 2.1515561 | F25: 41.400312 | G25: https://www.google.com/maps/@?api=1&map_action=pano&viewpoint=41.4003124653889,2.15155610489397 | H25: =HYPERLINK("https://www.google.com/maps/@?api=1&map_action=pano&viewpoint=41.4003124653889,2.15155610489397","Open GSV") -> Open GSV | I25: 1 | L25: 0 | P25: =IF(OR(I25=1,I25="1",I25=0,I25="0"),I25,IF(OR(J25=1,J25="1",J25=0,J25="0"),J25,IF(OR(K25=1,K25="1",K25=0,K25="0"),K25,"NA"))) -> 1 | Q25: =IF(OR(L25=1,L25="1",L25=0,L25="0"),L25,IF(OR(M25=1,M25="1",M25=0,M25="0"),M25,IF(OR(N25=1,N25="1",N25=0,N25="0"),N25,"NA"))) -> 0 | R25: =AND(ROUND(P25,0)=1, ROUND(Q25,0)=0) -> TRUE
A26: 24 | B26: ADD | C26: tract_0025 | D26: D2_C2 | E26: 2.1515394 | F26: 41.400205 | G26: https://www.google.com/maps/@?api=1&map_action=pano&viewpoint=41.400204647767,2.15153939610418 | H26: =HYPERLINK("https://www.google.com/maps/@?api=1&map_action=pano&viewpoint=41.400204647767,2.15153939610418","Open GSV") -> Open GSV | I26: 1 | L26: 0 | P26: =IF(OR(I26=1,I26="1",I26=0,I26="0"),I26,IF(OR(J26=1,J26="1",J26=0,J26="0"),J26,IF(OR(K26=1,K26="1",K26=0,K26="0"),K26,"NA"))) -> 1 | Q26: =IF(OR(L26=1,L26="1",L26=0,L26="0"),L26,IF(OR(M26=1,M26="1",M26=0,M26="0"),M26,IF(OR(N26=1,N26="1",N26=0,N26="0"),N26,"NA"))) -> 0 | R26: =AND(ROUND(P26,0)=1, ROUND(Q26,0)=0) -> TRUE
A27: 25 | B27: ADD | C27: tract_0028 | D27: D2_C2 | E27: 2.1868835 | F27: 41.413052 | G27: https://www.google.com/maps/@?api=1&map_action=pano&viewpoint=41.4130517909949,2.18688350279505 | H27: =HYPERLINK("https://www.google.com/maps/@?api=1&map_action=pano&viewpoint=41.4130517909949,2.18688350279505","Open GSV") -> Open GSV | I27: NA | J27: NA | K27: NA | L27: NA | M27: NA | N27: NA | O27: Realigment | P27: =IF(OR(I27=1,I27="1",I27=0,I27="0"),I27,IF(OR(J27=1,J27="1",J27=0,J27="0"),J27,IF(OR(K27=1,K27="1",K27=0,K27="0"),K27,"NA"))) -> NA | Q27: =IF(OR(L27=1,L27="1",L27=0,L27="0"),L27,IF(OR(M27=1,M27="1",M27=0,M27="0"),M27,IF(OR(N27=1,N27="1",N27=0,N27="0"),N27,"NA"))) -> NA | R27: =AND(ROUND(P27,0)=1, ROUND(Q27,0)=0) -> #VALUE!
A28: 26 | B28: ADD | C28: tract_0028 | D28: D2_C2 | E28: 2.1863076 | F28: 41.414041 | G28: https://www.google.com/maps/@?api=1&map_action=pano&viewpoint=41.4140408624214,2.18630763816643 | H28: =HYPERLINK("https://www.google.com/maps/@?api=1&map_action=pano&viewpoint=41.4140408624214,2.18630763816643","Open GSV") -> Open GSV | I28: NA | J28: 1 | L28: 0 | P28: =IF(OR(I28=1,I28="1",I28=0,I28="0"),I28,IF(OR(J28=1,J28="1",J28=0,J28="0"),J28,IF(OR(K28=1,K28="1",K28=0,K28="0"),K28,"NA"))) -> 1 | Q28: =IF(OR(L28=1,L28="1",L28=0,L28="0"),L28,IF(OR(M28=1,M28="1",M28=0,M28="0"),M28,IF(OR(N28=1,N28="1",N28=0,N28="0"),N28,"NA"))) -> 0 | R28: =AND(ROUND(P28,0)=1, ROUND(Q28,0)=0) -> TRUE
A29: 27 | B29: ADD | C29: tract_0030 | D29: D2_C2 | E29: 2.136257 | F29: 41.385981 | G29: https://www.google.com/maps/@?api=1&map_action=pano&viewpoint=41.3859805190524,2.13625700853397 | H29: =HYPERLINK("https://www.google.com/maps/@?api=1&map_action=pano&viewpoint=41.3859805190524,2.13625700853397","Open GSV") -> Open GSV | I29: NA | J29: NA | K29: 1 | L29: 0 | P29: =IF(OR(I29=1,I29="1",I29=0,I29="0"),I29,IF(OR(J29=1,J29="1",J29=0,J29="0"),J29,IF(OR(K29=1,K29="1",K29=0,K29="0"),K29,"NA"))) -> 1 | Q29: =IF(OR(L29=1,L29="1",L29=0,L29="0"),L29,IF(OR(M29=1,M29="1",M29=0,M29="0"),M29,IF(OR(N29=1,N29="1",N29=0,N29="0"),N29,"NA"))) -> 0 | R29: =AND(ROUND(P29,0)=1, ROUND(Q29,0)=0) -> TRUE
A30: 28 | B30: ADD | C30: tract_0030 | D30: D2_C2 | E30: 2.1385586 | F30: 41.385297 | G30: https://www.google.com/maps/@?api=1&map_action=pano&viewpoint=41.3852971271454,2.13855858286425 | H30: =HYPERLINK("https://www.google.com/maps/@?api=1&map_action=pano&viewpoint=41.3852971271454,2.13855858286425","Open GSV") -> Open GSV | I30: NA | J30: NA | K30: 1 | L30: 0 | P30: =IF(OR(I30=1,I30="1",I30=0,I30="0"),I30,IF(OR(J30=1,J30="1",J30=0,J30="0"),J30,IF(OR(K30=1,K30="1",K30=0,K30="0"),K30,"NA"))) -> 1 | Q30: =IF(OR(L30=1,L30="1",L30=0,L30="0"),L30,IF(OR(M30=1,M30="1",M30=0,M30="0"),M30,IF(OR(N30=1,N30="1",N30=0,N30="0"),N30,"NA"))) -> 0 | R30: =AND(ROUND(P30,0)=1, ROUND(Q30,0)=0) -> TRUE
A31: 29 | B31: ADD | C31: tract_0031 | D31: D2_C3 | E31: 2.1864299 | F31: 41.391188 | G31: https://www.google.com/maps/@?api=1&map_action=pano&viewpoint=41.3911878676426,2.18642991571189 | H31: =HYPERLINK("https://www.google.com/maps/@?api=1&map_action=pano&viewpoint=41.3911878676426,2.18642991571189","Open GSV") -> Open GSV | I31: 1 | L31: 0 | O31: Peg moved both | P31: =IF(OR(I31=1,I31="1",I31=0,I31="0"),I31,IF(OR(J31=1,J31="1",J31=0,J31="0"),J31,IF(OR(K31=1,K31="1",K31=0,K31="0"),K31,"NA"))) -> 1 | Q31: =IF(OR(L31=1,L31="1",L31=0,L31="0"),L31,IF(OR(M31=1,M31="1",M31=0,M31="0"),M31,IF(OR(N31=1,N31="1",N31=0,N31="0"),N31,"NA"))) -> 0 | R31: =AND(ROUND(P31,0)=1, ROUND(Q31,0)=0) -> TRUE
A32: 30 | B32: ADD | C32: tract_0031 | D32: D2_C3 | E32: 2.185338 | F32: 41.390375 | G32: https://www.google.com/maps/@?api=1&map_action=pano&viewpoint=41.3903749358271,2.18533799661021 | H32: =HYPERLINK("https://www.google.com/maps/@?api=1&map_action=pano&viewpoint=41.3903749358271,2.18533799661021","Open GSV") -> Open GSV | I32: 1 | L32: 0 | O32: Peg moved both | P32: =IF(OR(I32=1,I32="1",I32=0,I32="0"),I32,IF(OR(J32=1,J32="1",J32=0,J32="0"),J32,IF(OR(K32=1,K32="1",K32=0,K32="0"),K32,"NA"))) -> 1 | Q32: =IF(OR(L32=1,L32="1",L32=0,L32="0"),L32,IF(OR(M32=1,M32="1",M32=0,M32="0"),M32,IF(OR(N32=1,N32="1",N32=0,N32="0"),N32,"NA"))) -> 0 | R32: =AND(ROUND(P32,0)=1, ROUND(Q32,0)=0) -> TRUE
A33: 31 | B33: ADD | C33: tract_0035 | D33: D2_C3 | E33: 2.1589756 | F33: 41.382643 | G33: https://www.google.com/maps/@?api=1&map_action=pano&viewpoint=41.3826431790481,2.15897555292766 | H33: =HYPERLINK("https://www.google.com/maps/@?api=1&map_action=pano&viewpoint=41.3826431790481,2.15897555292766","Open GSV") -> Open GSV | I33: NA | J33: NA | K33: NA | L33: NA | M33: NA | N33: NA | O33: Realigment | P33: =IF(OR(I33=1,I33="1",I33=0,I33="0"),I33,IF(OR(J33=1,J33="1",J33=0,J33="0"),J33,IF(OR(K33=1,K33="1",K33=0,K33="0"),K33,"NA"))) -> NA | Q33: =IF(OR(L33=1,L33="1",L33=0,L33="0"),L33,IF(OR(M33=1,M33="1",M33=0,M33="0"),M33,IF(OR(N33=1,N33="1",N33=0,N33="0"),N33,"NA"))) -> NA | R33: =AND(ROUND(P33,0)=1, ROUND(Q33,0)=0) -> #VALUE!
A34: 32 | B34: ADD | C34: tract_0036 | D34: D2_C3 | E34: 2.153705 | F34: 41.398118 | G34: https://www.google.com/maps/@?api=1&map_action=pano&viewpoint=41.3981184632183,2.15370501205099 | H34: =HYPERLINK("https://www.google.com/maps/@?api=1&map_action=pano&viewpoint=41.3981184632183,2.15370501205099","Open GSV") -> Open GSV | I34: 1 | L34: 0 | P34: =IF(OR(I34=1,I34="1",I34=0,I34="0"),I34,IF(OR(J34=1,J34="1",J34=0,J34="0"),J34,IF(OR(K34=1,K34="1",K34=0,K34="0"),K34,"NA"))) -> 1 | Q34: =IF(OR(L34=1,L34="1",L34=0,L34="0"),L34,IF(OR(M34=1,M34="1",M34=0,M34="0"),M34,IF(OR(N34=1,N34="1",N34=0,N34="0"),N34,"NA"))) -> 0 | R34: =AND(ROUND(P34,0)=1, ROUND(Q34,0)=0) -> TRUE
A35: 33 | B35: ADD | C35: tract_0036 | D35: D2_C3 | E35: 2.1537502 | F35: 41.398133 | G35: https://www.google.com/maps/@?api=1&map_action=pano&viewpoint=41.3981332109611,2.1537501547691 | H35: =HYPERLINK("https://www.google.com/maps/@?api=1&map_action=pano&viewpoint=41.3981332109611,2.1537501547691","Open GSV") -> Open GSV | I35: 1 | L35: 0 | P35: =IF(OR(I35=1,I35="1",I35=0,I35="0"),I35,IF(OR(J35=1,J35="1",J35=0,J35="0"),J35,IF(OR(K35=1,K35="1",K35=0,K35="0"),K35,"NA"))) -> 1 | Q35: =IF(OR(L35=1,L35="1",L35=0,L35="0"),L35,IF(OR(M35=1,M35="1",M35=0,M35="0"),M35,IF(OR(N35=1,N35="1",N35=0,N35="0"),N35,"NA"))) -> 0 | R35: =AND(ROUND(P35,0)=1, ROUND(Q35,0)=0) -> TRUE
A36: 34 | B36: ADD | C36: tract_0041 | D36: D3_C1 | E36: 2.1240095 | F36: 41.375664 | G36: https://www.google.com/maps/@?api=1&map_action=pano&viewpoint=41.3756644128399,2.1240095291374 | H36: =HYPERLINK("https://www.google.com/maps/@?api=1&map_action=pano&viewpoint=41.3756644128399,2.1240095291374","Open GSV") -> Open GSV | I36: 1 | L36: 0 | P36: =IF(OR(I36=1,I36="1",I36=0,I36="0"),I36,IF(OR(J36=1,J36="1",J36=0,J36="0"),J36,IF(OR(K36=1,K36="1",K36=0,K36="0"),K36,"NA"))) -> 1 | Q36: =IF(OR(L36=1,L36="1",L36=0,L36="0"),L36,IF(OR(M36=1,M36="1",M36=0,M36="0"),M36,IF(OR(N36=1,N36="1",N36=0,N36="0"),N36,"NA"))) -> 0 | R36: =AND(ROUND(P36,0)=1, ROUND(Q36,0)=0) -> TRUE
A37: 35 | B37: ADD | C37: tract_0043 | D37: D3_C2 | E37: 2.130759 | F37: 41.375087 | G37: https://www.google.com/maps/@?api=1&map_action=pano&viewpoint=41.3750869481267,2.13075902951078 | H37: =HYPERLINK("https://www.google.com/maps/@?api=1&map_action=pano&viewpoint=41.3750869481267,2.13075902951078","Open GSV") -> Open GSV | I37: 0 | J37: NA | L37: 0 | O37: Peg moved both | P37: =IF(OR(I37=1,I37="1",I37=0,I37="0"),I37,IF(OR(J37=1,J37="1",J37=0,J37="0"),J37,IF(OR(K37=1,K37="1",K37=0,K37="0"),K37,"NA"))) -> 0 | Q37: =IF(OR(L37=1,L37="1",L37=0,L37="0"),L37,IF(OR(M37=1,M37="1",M37=0,M37="0"),M37,IF(OR(N37=1,N37="1",N37=0,N37="0"),N37,"NA"))) -> 0 | R37: =AND(ROUND(P37,0)=1, ROUND(Q37,0)=0) -> FALSE
A38: 36 | B38: ADD | C38: tract_0043 | D38: D3_C2 | E38: 2.1311878 | F38: 41.37384 | G38: https://www.google.com/maps/@?api=1&map_action=pano&viewpoint=41.3738399462803,2.13118777902404 | H38: =HYPERLINK("https://www.google.com/maps/@?api=1&map_action=pano&viewpoint=41.3738399462803,2.13118777902404","Open GSV") -> Open GSV | I38: NA | J38: NA | K38: 0 | L38: NA | M38: 0 | P38: =IF(OR(I38=1,I38="1",I38=0,I38="0"),I38,IF(OR(J38=1,J38="1",J38=0,J38="0"),J38,IF(OR(K38=1,K38="1",K38=0,K38="0"),K38,"NA"))) -> 0 | Q38: =IF(OR(L38=1,L38="1",L38=0,L38="0"),L38,IF(OR(M38=1,M38="1",M38=0,M38="0"),M38,IF(OR(N38=1,N38="1",N38=0,N38="0"),N38,"NA"))) -> 0 | R38: =AND(ROUND(P38,0)=1, ROUND(Q38,0)=0) -> FALSE
A39: 37 | B39: ADD | C39: tract_0044 | D39: D3_C2 | E39: 2.1797608 | F39: 41.41188 | G39: https://www.google.com/maps/@?api=1&map_action=pano&viewpoint=41.4118804921771,2.17976081270431 | H39: =HYPERLINK("https://www.google.com/maps/@?api=1&map_action=pano&viewpoint=41.4118804921771,2.17976081270431","Open GSV") -> Open GSV | I39: 1 | L39: 0 | O39: Peg moved 23 | P39: =IF(OR(I39=1,I39="1",I39=0,I39="0"),I39,IF(OR(J39=1,J39="1",J39=0,J39="0"),J39,IF(OR(K39=1,K39="1",K39=0,K39="0"),K39,"NA"))) -> 1 | Q39: =IF(OR(L39=1,L39="1",L39=0,L39="0"),L39,IF(OR(M39=1,M39="1",M39=0,M39="0"),M39,IF(OR(N39=1,N39="1",N39=0,N39="0"),N39,"NA"))) -> 0 | R39: =AND(ROUND(P39,0)=1, ROUND(Q39,0)=0) -> TRUE
A40: 38 | B40: ADD | C40: tract_0044 | D40: D3_C2 | E40: 2.1808908 | F40: 41.412745 | G40: https://www.google.com/maps/@?api=1&map_action=pano&viewpoint=41.4127447371871,2.180890772398 | H40: =HYPERLINK("https://www.google.com/maps/@?api=1&map_action=pano&viewpoint=41.4127447371871,2.180890772398","Open GSV") -> Open GSV | I40: 0 | J40: NA | L40: 0 | O40: Peg moved 23; in construction? | P40: =IF(OR(I40=1,I40="1",I40=0,I40="0"),I40,IF(OR(J40=1,J40="1",J40=0,J40="0"),J40,IF(OR(K40=1,K40="1",K40=0,K40="0"),K40,"NA"))) -> 0 | Q40: =IF(OR(L40=1,L40="1",L40=0,L40="0"),L40,IF(OR(M40=1,M40="1",M40=0,M40="0"),M40,IF(OR(N40=1,N40="1",N40=0,N40="0"),N40,"NA"))) -> 0 | R40: =AND(ROUND(P40,0)=1, ROUND(Q40,0)=0) -> FALSE
...

Sheet ADD_vgp
I1: 2023 | L1: 2015
A2: id | B2: class | C2: tract_id | D2: stratum | E2: lon | F2: lat | G2: gsv_link | H2: GSV | I2: present_2023 | J2: present_2024 | K2: present_2022 | L2: present_2015 | M2: present_2014 | N2: present_2016 | O2: notes | P2: present_followup | Q2: present_baseline | R2: Match
A3: 1 | B3: ADD | C3: tract_0001 | D3: D1_C1 | E3: 2.1121109 | F3: 41.390968 | G3: https://www.google.com/maps/@?api=1&map_action=pano&viewpoint=41.3909679997347,2.11211089874738 | H3: =HYPERLINK("https://www.google.com/maps/@?api=1&map_action=pano&viewpoint=41.3909679997347,2.11211089874738","Open GSV") -> Open GSV | I3: NA | J3: NA | K3: 1 | L3: 0 | O3: peg moved 2022 and 2015 | P3: =IF(OR(I3=1,I3="1",I3=0,I3="0"),I3,IF(OR(J3=1,J3="1",J3=0,J3="0"),J3,IF(OR(K3=1,K3="1",K3=0,K3="0"),K3,"NA"))) -> 1 | Q3: =IF(OR(L3=1,L3="1",L3=0,L3="0"),L3,IF(OR(M3=1,M3="1",M3=0,M3="0"),M3,IF(OR(N3=1,N3="1",N3=0,N3="0"),N3,"NA"))) -> 0 | R3: =AND(ROUND(P3,0)=1, ROUND(Q3,0)=0) -> TRUE
A4: 2 | B4: ADD | C4: tract_0003 | D4: D1_C1 | E4: 2.1803101 | F4: 41.458146 | G4: https://www.google.com/maps/@?api=1&map_action=pano&viewpoint=41.4581456267453,2.18031012416 | H4: =HYPERLINK("https://www.google.com/maps/@?api=1&map_action=pano&viewpoint=41.4581456267453,2.18031012416","Open GSV") -> Open GSV | I4: 1 | L4: NA | M4: 1 | O4: peg moved 2023; 2015 then 2014 checked -> Always existed -> FALSE ADD | P4: =IF(OR(I4=1,I4="1",I4=0,I4="0"),I4,IF(OR(J4=1,J4="1",J4=0,J4="0"),J4,IF(OR(K4=1,K4="1",K4=0,K4="0"),K4,"NA"))) -> 1 | Q4: =IF(OR(L4=1,L4="1",L4=0,L4="0"),L4,IF(OR(M4=1,M4="1",M4=0,M4="0"),M4,IF(OR(N4=1,N4="1",N4=0,N4="0"),N4,"NA"))) -> 1 | R4: =AND(ROUND(P4,0)=1, ROUND(Q4,0)=0) -> FALSE
A5: 3 | B5: ADD | C5: tract_0004 | D5: D1_C1 | E5: 2.1408527 | F5: 41.413422 | G5: https://www.google.com/maps/@?api=1&map_action=pano&viewpoint=41.4134215995416,2.14085269668676 | H5: =HYPERLINK("https://www.google.com/maps/@?api=1&map_action=pano&viewpoint=41.4134215995416,2.14085269668676","Open GSV") -> Open GSV | I5: NA | J5: 1 | L5: 0 | O5: peg moved 2024; | P5: =IF(OR(I5=1,I5="1",I5=0,I5="0"),I5,IF(OR(J5=1,J5="1",J5=0,J5="0"),J5,IF(OR(K5=1,K5="1",K5=0,K5="0"),K5,"NA"))) -> 1 | Q5: =IF(OR(L5=1,L5="1",L5=0,L5="0"),L5,IF(OR(M5=1,M5="1",M5=0,M5="0"),M5,IF(OR(N5=1,N5="1",N5=0,N5="0"),N5,"NA"))) -> 0 | R5: =AND(ROUND(P5,0)=1, ROUND(Q5,0)=0) -> TRUE
A6: 4 | B6: ADD | C6: tract_0006 | D6: D1_C1 | E6: 2.2011317 | F6: 41.426283 | G6: https://www.google.com/maps/@?api=1&map_action=pano&viewpoint=41.4262832087554,2.20113165987653 | H6: =HYPERLINK("https://www.google.com/maps/@?api=1&map_action=pano&viewpoint=41.4262832087554,2.20113165987653","Open GSV") -> Open GSV | I6: 1 | L6: 0 | P6: =IF(OR(I6=1,I6="1",I6=0,I6="0"),I6,IF(OR(J6=1,J6="1",J6=0,J6="0"),J6,IF(OR(K6=1,K6="1",K6=0,K6="0"),K6,"NA"))) -> 1 | Q6: =IF(OR(L6=1,L6="1",L6=0,L6="0"),L6,IF(OR(M6=1,M6="1",M6=0,M6="0"),M6,IF(OR(N6=1,N6="1",N6=0,N6="0"),N6,"NA"))) -> 0 | R6: =AND(ROUND(P6,0)=1, ROUND(Q6,0)=0) -> TRUE
A7: 5 | B7: ADD | C7: tract_0006 | D7: D1_C1 | E7: 2.2001191 | F7: 41.426033 | G7: https://www.google.com/maps/@?api=1&map_action=pano&viewpoint=41.4260327049088,2.2001190522901 | H7: =HYPERLINK("https://www.google.com/maps/@?api=1&map_action=pano&viewpoint=41.4260327049088,2.2001190522901","Open GSV") -> Open GSV | I7: 1 | L7: 0 | P7: =IF(OR(I7=1,I7="1",I7=0,I7="0"),I7,IF(OR(J7=1,J7="1",J7=0,J7="0"),J7,IF(OR(K7=1,K7="1",K7=0,K7="0"),K7,"NA"))) -> 1 | Q7: =IF(OR(L7=1,L7="1",L7=0,L7="0"),L7,IF(OR(M7=1,M7="1",M7=0,M7="0"),M7,IF(OR(N7=1,N7="1",N7=0,N7="0"),N7,"NA"))) -> 0 | R7: =AND(ROUND(P7,0)=1, ROUND(Q7,0)=0) -> TRUE
A8: 6 | B8: ADD | C8: tract_0007 | D8: D1_C2 | E8: 2.1347574 | F8: 41.389964 | G8: https://www.google.com/maps/@?api=1&map_action=pano&viewpoint=41.3899636143591,2.134757401236 | H8: =HYPERLINK("https://www.google.com/maps/@?api=1&map_action=pano&viewpoint=41.3899636143591,2.134757401236","Open GSV") -> Open GSV | I8: NA | J8: 0 | L8: 0 | O8: peg moved 2023, 2024 checked and not found -> Never existed -> FALSE ADD | P8: =IF(OR(I8=1,I8="1",I8=0,I8="0"),I8,IF(OR(J8=1,J8="1",J8=0,J8="0"),J8,IF(OR(K8=1,K8="1",K8=0,K8="0"),K8,"NA"))) -> 0 | Q8: =IF(OR(L8=1,L8="1",L8=0,L8="0"),L8,IF(OR(M8=1,M8="1",M8=0,M8="0"),M8,IF(OR(N8=1,N8="1",N8=0,N8="0"),N8,"NA"))) -> 0 | R8: =AND(ROUND(P8,0)=1, ROUND(Q8,0)=0) -> FALSE
A9: 7 | B9: ADD | C9: tract_0007 | D9: D1_C2 | E9: 2.1340276 | F9: 41.388185 | G9: https://www.google.com/maps/@?api=1&map_action=pano&viewpoint=41.3881854073843,2.13402755812854 | H9: =HYPERLINK("https://www.google.com/maps/@?api=1&map_action=pano&viewpoint=41.3881854073843,2.13402755812854","Open GSV") -> Open GSV | I9: 1 | L9: 0 | O9: peg moved 2023, | P9: =IF(OR(I9=1,I9="1",I9=0,I9="0"),I9,IF(OR(J9=1,J9="1",J9=0,J9="0"),J9,IF(OR(K9=1,K9="1",K9=0,K9="0"),K9,"NA"))) -> 1 | Q9: =IF(OR(L9=1,L9="1",L9=0,L9="0"),L9,IF(OR(M9=1,M9="1",M9=0,M9="0"),M9,IF(OR(N9=1,N9="1",N9=0,N9="0"),N9,"NA"))) -> 0 | R9: =AND(ROUND(P9,0)=1, ROUND(Q9,0)=0) -> TRUE
A10: 8 | B10: ADD | C10: tract_0009 | D10: D1_C2 | E10: 2.1988167 | F10: 41.416812 | G10: https://www.google.com/maps/@?api=1&map_action=pano&viewpoint=41.4168121764961,2.19881673887713 | H10: =HYPERLINK("https://www.google.com/maps/@?api=1&map_action=pano&viewpoint=41.4168121764961,2.19881673887713","Open GSV") -> Open GSV | I10: 1 | L10: NA | M10: 0 | O10: peg moved 2015 (roadworks), | P10: =IF(OR(I10=1,I10="1",I10=0,I10="0"),I10,IF(OR(J10=1,J10="1",J10=0,J10="0"),J10,IF(OR(K10=1,K10="1",K10=0,K10="0"),K10,"NA"))) -> 1 | Q10: =IF(OR(L10=1,L10="1",L10=0,L10="0"),L10,IF(OR(M10=1,M10="1",M10=0,M10="0"),M10,IF(OR(N10=1,N10="1",N10=0,N10="0"),N10,"NA"))) -> 0 | R10: =AND(ROUND(P10,0)=1, ROUND(Q10,0)=0) -> TRUE
A11: 9 | B11: ADD | C11: tract_0010 | D11: D1_C2 | E11: 2.1746102 | F11: 41.416865 | G11: https://www.google.com/maps/@?api=1&map_action=pano&viewpoint=41.4168653577514,2.17461017557639 | H11: =HYPERLINK("https://www.google.com/maps/@?api=1&map_action=pano&viewpoint=41.4168653577514,2.17461017557639","Open GSV") -> Open GSV | I11: 1 | L11: 0 | P11: =IF(OR(I11=1,I11="1",I11=0,I11="0"),I11,IF(OR(J11=1,J11="1",J11=0,J11="0"),J11,IF(OR(K11=1,K11="1",K11=0,K11="0"),K11,"NA"))) -> 1 | Q11: =IF(OR(L11=1,L11="1",L11=0,L11="0"),L11,IF(OR(M11=1,M11="1",M11=0,M11="0"),M11,IF(OR(N11=1,N11="1",N11=0,N11="0"),N11,"NA"))) -> 0 | R11: =AND(ROUND(P11,0)=1, ROUND(Q11,0)=0) -> TRUE
A12: 10 | B12: ADD | C12: tract_0010 | D12: D1_C2 | E12: 2.172051 | F12: 41.414976 | G12: https://www.google.com/maps/@?api=1&map_action=pano&viewpoint=41.414975730964,2.17205102853822 | H12: =HYPERLINK("https://www.google.com/maps/@?api=1&map_action=pano&viewpoint=41.414975730964,2.17205102853822","Open GSV") -> Open GSV | I12: 1 | L12: 1 | O12: FALSE ADD -> REALIGN | P12: =IF(OR(I12=1,I12="1",I12=0,I12="0"),I12,IF(OR(J12=1,J12="1",J12=0,J12="0"),J12,IF(OR(K12=1,K12="1",K12=0,K12="0"),K12,"NA"))) -> 1 | Q12: =IF(OR(L12=1,L12="1",L12=0,L12="0"),L12,IF(OR(M12=1,M12="1",M12=0,M12="0"),M12,IF(OR(N12=1,N12="1",N12=0,N12="0"),N12,"NA"))) -> 1 | R12: =AND(ROUND(P12,0)=1, ROUND(Q12,0)=0) -> FALSE
A13: 11 | B13: ADD | C13: tract_0011 | D13: D1_C2 | E13: 2.2075546 | F13: 41.420448 | G13: https://www.google.com/maps/@?api=1&map_action=pano&viewpoint=41.4204481302083,2.2075546110796 | H13: =HYPERLINK("https://www.google.com/maps/@?api=1&map_action=pano&viewpoint=41.4204481302083,2.2075546110796","Open GSV") -> Open GSV | I13: 1 | L13: NA | M13: 1 | O13: peg moved 2023; 2015 then 2014 checked -> Always existed -> FALSE ADD | P13: =IF(OR(I13=1,I13="1",I13=0,I13="0"),I13,IF(OR(J13=1,J13="1",J13=0,J13="0"),J13,IF(OR(K13=1,K13="1",K13=0,K13="0"),K13,"NA"))) -> 1 | Q13: =IF(OR(L13=1,L13="1",L13=0,L13="0"),L13,IF(OR(M13=1,M13="1",M13=0,M13="0"),M13,IF(OR(N13=1,N13="1",N13=0,N13="0"),N13,"NA"))) -> 1 | R13: =AND(ROUND(P13,0)=1, ROUND(Q13,0)=0) -> FALSE
A14: 12 | B14: ADD | C14: tract_0011 | D14: D1_C2 | E14: 2.2079426 | F14: 41.420245 | G14: https://www.google.com/maps/@?api=1&map_action=pano&viewpoint=41.4202454258576,2.20794256929774 | H14: =HYPERLINK("https://www.google.com/maps/@?api=1&map_action=pano&viewpoint=41.4202454258576,2.20794256929774","Open GSV") -> Open GSV | I14: 1 | L14: NA | M14: 1 | O14: peg moved 2023; 2015 then 2014 checked -> Always existed -> FALSE ADD | P14: =IF(OR(I14=1,I14="1",I14=0,I14="0"),I14,IF(OR(J14=1,J14="1",J14=0,J14="0"),J14,IF(OR(K14=1,K14="1",K14=0,K14="0"),K14,"NA"))) -> 1 | Q14: =IF(OR(L14=1,L14="1",L14=0,L14="0"),L14,IF(OR(M14=1,M14="1",M14=0,M14="0"),M14,IF(OR(N14=1,N14="1",N14=0,N14="0"),N14,"NA"))) -> 1 | R14: =AND(ROUND(P14,0)=1, ROUND(Q14,0)=0) -> FALSE
A15: 13 | B15: ADD | C15: tract_0012 | D15: D1_C2 | E15: 2.1609809 | F15: 41.412109 | G15: https://www.google.com/maps/@?api=1&map_action=pano&viewpoint=41.4121092794043,2.16098092184219 | H15: =HYPERLINK("https://www.google.com/maps/@?api=1&map_action=pano&viewpoint=41.4121092794043,2.16098092184219","Open GSV") -> Open GSV | I15: 1 | L15: 0 | P15: =IF(OR(I15=1,I15="1",I15=0,I15="0"),I15,IF(OR(J15=1,J15="1",J15=0,J15="0"),J15,IF(OR(K15=1,K15="1",K15=0,K15="0"),K15,"NA"))) -> 1 | Q15: =IF(OR(L15=1,L15="1",L15=0,L15="0"),L15,IF(OR(M15=1,M15="1",M15=0,M15="0"),M15,IF(OR(N15=1,N15="1",N15=0,N15="0"),N15,"NA"))) -> 0 | R15: =AND(ROUND(P15,0)=1, ROUND(Q15,0)=0) -> TRUE
A16: 14 | B16: ADD | C16: tract_0012 | D16: D1_C2 | E16: 2.1617583 | F16: 41.412547 | G16: https://www.google.com/maps/@?api=1&map_action=pano&viewpoint=41.4125465819168,2.16175831110785 | H16: =HYPERLINK("https://www.google.com/maps/@?api=1&map_action=pano&viewpoint=41.4125465819168,2.16175831110785","Open GSV") -> Open GSV | I16: NA | J16: 1 | L16: 0 | O16: 2023 underground, 2024 same point overground / 2015 only underground if peg not moved before year switch / "REAL ADD" but many steps to check. | P16: =IF(OR(I16=1,I16="1",I16=0,I16="0"),I16,IF(OR(J16=1,J16="1",J16=0,J16="0"),J16,IF(OR(K16=1,K16="1",K16=0,K16="0"),K16,"NA"))) -> 1 | Q16: =IF(OR(L16=1,L16="1",L16=0,L16="0"),L16,IF(OR(M16=1,M16="1",M16=0,M16="0"),M16,IF(OR(N16=1,N16="1",N16=0,N16="0"),N16,"NA"))) -> 0 | R16: =AND(ROUND(P16,0)=1, ROUND(Q16,0)=0) -> TRUE
A17: 15 | B17: ADD | C17: tract_0013 | D17: D1_C3 | E17: 2.2007726 | F17: 41.394521 | G17: https://www.google.com/maps/@?api=1&map_action=pano&viewpoint=41.3945206907087,2.20077256303846 | H17: =HYPERLINK("https://www.google.com/maps/@?api=1&map_action=pano&viewpoint=41.3945206907087,2.20077256303846","Open GSV") -> Open GSV | I17: 1 | L17: 0 | O17: peg moved 2023 | P17: =IF(OR(I17=1,I17="1",I17=0,I17="0"),I17,IF(OR(J17=1,J17="1",J17=0,J17="0"),J17,IF(OR(K17=1,K17="1",K17=0,K17="0"),K17,"NA"))) -> 1 | Q17: =IF(OR(L17=1,L17="1",L17=0,L17="0"),L17,IF(OR(M17=1,M17="1",M17=0,M17="0"),M17,IF(OR(N17=1,N17="1",N17=0,N17="0"),N17,"NA"))) -> 0 | R17: =AND(ROUND(P17,0)=1, ROUND(Q17,0)=0) -> TRUE
A18: 16 | B18: ADD | C18: tract_0013 | D18: D1_C3 | E18: 2.2010092 | F18: 41.394719 | G18: https://www.google.com/maps/@?api=1&map_action=pano&viewpoint=41.394718915396,2.20100922656311 | H18: =HYPERLINK("https://www.google.com/maps/@?api=1&map_action=pano&viewpoint=41.394718915396,2.20100922656311","Open GSV") -> Open GSV | I18: 1 | L18: 0 | P18: =IF(OR(I18=1,I18="1",I18=0,I18="0"),I18,IF(OR(J18=1,J18="1",J18=0,J18="0"),J18,IF(OR(K18=1,K18="1",K18=0,K18="0"),K18,"NA"))) -> 1 | Q18: =IF(OR(L18=1,L18="1",L18=0,L18="0"),L18,IF(OR(M18=1,M18="1",M18=0,M18="0"),M18,IF(OR(N18=1,N18="1",N18=0,N18="0"),N18,"NA"))) -> 0 | R18: =AND(ROUND(P18,0)=1, ROUND(Q18,0)=0) -> TRUE
A19: 17 | B19: ADD | C19: tract_0017 | D19: D1_C3 | E19: 2.1451506 | F19: 41.376224 | G19: https://www.google.com/maps/@?api=1&map_action=pano&viewpoint=41.3762241357195,2.14515055931621 | H19: =HYPERLINK("https://www.google.com/maps/@?api=1&map_action=pano&viewpoint=41.3762241357195,2.14515055931621","Open GSV") -> Open GSV | I19: 1 | L19: 0 | O19: 2015 Lanes with roadpaint indicating bike presence? | P19: =IF(OR(I19=1,I19="1",I19=0,I19="0"),I19,IF(OR(J19=1,J19="1",J19=0,J19="0"),J19,IF(OR(K19=1,K19="1",K19=0,K19="0"),K19,"NA"))) -> 1 | Q19: =IF(OR(L19=1,L19="1",L19=0,L19="0"),L19,IF(OR(M19=1,M19="1",M19=0,M19="0"),M19,IF(OR(N19=1,N19="1",N19=0,N19="0"),N19,"NA"))) -> 0 | R19: =AND(ROUND(P19,0)=1, ROUND(Q19,0)=0) -> TRUE
A20: 18 | B20: ADD | C20: tract_0017 | D20: D1_C3 | E20: 2.1455917 | F20: 41.376413 | G20: https://www.google.com/maps/@?api=1&map_action=pano&viewpoint=41.3764134914288,2.14559167922172 | H20: =HYPERLINK("https://www.google.com/maps/@?api=1&map_action=pano&viewpoint=41.3764134914288,2.14559167922172","Open GSV") -> Open GSV | I20: 1 | L20: 0 | O20: 2015 Lanes with roadpaint indicating bike presence? | P20: =IF(OR(I20=1,I20="1",I20=0,I20="0"),I20,IF(OR(J20=1,J20="1",J20=0,J20="0"),J20,IF(OR(K20=1,K20="1",K20=0,K20="0"),K20,"NA"))) -> 1 | Q20: =IF(OR(L20=1,L20="1",L20=0,L20="0"),L20,IF(OR(M20=1,M20="1",M20=0,M20="0"),M20,IF(OR(N20=1,N20="1",N20=0,N20="0"),N20,"NA"))) -> 0 | R20: =AND(ROUND(P20,0)=1, ROUND(Q20,0)=0) -> TRUE
A21: 19 | B21: ADD | C21: tract_0018 | D21: D1_C3 | E21: 2.1828475 | F21: 41.405575 | G21: https://www.google.com/maps/@?api=1&map_action=pano&viewpoint=41.4055753756871,2.18284748138898 | H21: =HYPERLINK("https://www.google.com/maps/@?api=1&map_action=pano&viewpoint=41.4055753756871,2.18284748138898","Open GSV") -> Open GSV | I21: 1 | L21: 0 | P21: =IF(OR(I21=1,I21="1",I21=0,I21="0"),I21,IF(OR(J21=1,J21="1",J21=0,J21="0"),J21,IF(OR(K21=1,K21="1",K21=0,K21="0"),K21,"NA"))) -> 1 | Q21: =IF(OR(L21=1,L21="1",L21=0,L21="0"),L21,IF(OR(M21=1,M21="1",M21=0,M21="0"),M21,IF(OR(N21=1,N21="1",N21=0,N21="0"),N21,"NA"))) -> 0 | R21: =AND(ROUND(P21,0)=1, ROUND(Q21,0)=0) -> TRUE
A22: 20 | B22: ADD | C22: tract_0018 | D22: D1_C3 | E22: 2.1828597 | F22: 41.403095 | G22: https://www.google.com/maps/@?api=1&map_action=pano&viewpoint=41.403094880684,2.18285971742863 | H22: =HYPERLINK("https://www.google.com/maps/@?api=1&map_action=pano&viewpoint=41.403094880684,2.18285971742863","Open GSV") -> Open GSV | I22: 1 | L22: 0 | O22: peg moved 2023 | P22: =IF(OR(I22=1,I22="1",I22=0,I22="0"),I22,IF(OR(J22=1,J22="1",J22=0,J22="0"),J22,IF(OR(K22=1,K22="1",K22=0,K22="0"),K22,"NA"))) -> 1 | Q22: =IF(OR(L22=1,L22="1",L22=0,L22="0"),L22,IF(OR(M22=1,M22="1",M22=0,M22="0"),M22,IF(OR(N22=1,N22="1",N22=0,N22="0"),N22,"NA"))) -> 0 | R22: =AND(ROUND(P22,0)=1, ROUND(Q22,0)=0) -> TRUE
A23: 21 | B23: ADD | C23: tract_0023 | D23: D2_C1 | E23: 2.1758556 | F23: 41.428756 | G23: https://www.google.com/maps/@?api=1&map_action=pano&viewpoint=41.4287555466715,2.17585558557915 | H23: =HYPERLINK("https://www.google.com/maps/@?api=1&map_action=pano&viewpoint=41.4287555466715,2.17585558557915","Open GSV") -> Open GSV | I23: 1 | L23: NA | M23: 1 | O23: peg moved both to confirm it is and was a bike lane; 2015 then 2014 checked -> Always existed -> FALSE ADD | P23: =IF(OR(I23=1,I23="1",I23=0,I23="0"),I23,IF(OR(J23=1,J23="1",J23=0,J23="0"),J23,IF(OR(K23=1,K23="1",K23=0,K23="0"),K23,"NA"))) -> 1 | Q23: =IF(OR(L23=1,L23="1",L23=0,L23="0"),L23,IF(OR(M23=1,M23="1",M23=0,M23="0"),M23,IF(OR(N23=1,N23="1",N23=0,N23="0"),N23,"NA"))) -> 1 | R23: =AND(ROUND(P23,0)=1, ROUND(Q23,0)=0) -> FALSE
A24: 22 | B24: ADD | C24: tract_0024 | D24: D2_C1 | E24: 2.1908314 | F24: 41.440995 | G24: https://www.google.com/maps/@?api=1&map_action=pano&viewpoint=41.4409954760919,2.19083141351904 | H24: =HYPERLINK("https://www.google.com/maps/@?api=1&map_action=pano&viewpoint=41.4409954760919,2.19083141351904","Open GSV") -> Open GSV | I24: 1 | L24: NA | M24: 1 | O24: Paint on sidewalk indicates bikelane 2023, same paint in 2025 and 2014 -> Always ecisted --> FALSE ADD | P24: =IF(OR(I24=1,I24="1",I24=0,I24="0"),I24,IF(OR(J24=1,J24="1",J24=0,J24="0"),J24,IF(OR(K24=1,K24="1",K24=0,K24="0"),K24,"NA"))) -> 1 | Q24: =IF(OR(L24=1,L24="1",L24=0,L24="0"),L24,IF(OR(M24=1,M24="1",M24=0,M24="0"),M24,IF(OR(N24=1,N24="1",N24=0,N24="0"),N24,"NA"))) -> 1 | R24: =AND(ROUND(P24,0)=1, ROUND(Q24,0)=0) -> FALSE
A25: 23 | B25: ADD | C25: tract_0025 | D25: D2_C2 | E25: 2.1515561 | F25: 41.400312 | G25: https://www.google.com/maps/@?api=1&map_action=pano&viewpoint=41.4003124653889,2.15155610489397 | H25: =HYPERLINK("https://www.google.com/maps/@?api=1&map_action=pano&viewpoint=41.4003124653889,2.15155610489397","Open GSV") -> Open GSV | I25: 1 | L25: 0 | P25: =IF(OR(I25=1,I25="1",I25=0,I25="0"),I25,IF(OR(J25=1,J25="1",J25=0,J25="0"),J25,IF(OR(K25=1,K25="1",K25=0,K25="0"),K25,"NA"))) -> 1 | Q25: =IF(OR(L25=1,L25="1",L25=0,L25="0"),L25,IF(OR(M25=1,M25="1",M25=0,M25="0"),M25,IF(OR(N25=1,N25="1",N25=0,N25="0"),N25,"NA"))) -> 0 | R25: =AND(ROUND(P25,0)=1, ROUND(Q25,0)=0) -> TRUE
A26: 24 | B26: ADD | C26: tract_0025 | D26: D2_C2 | E26: 2.1515394 | F26: 41.400205 | G26: https://www.google.com/maps/@?api=1&map_action=pano&viewpoint=41.400204647767,2.15153939610418 | H26: =HYPERLINK("https://www.google.com/maps/@?api=1&map_action=pano&viewpoint=41.400204647767,2.15153939610418","Open GSV") -> Open GSV | I26: 1 | L26: 0 | P26: =IF(OR(I26=1,I26="1",I26=0,I26="0"),I26,IF(OR(J26=1,J26="1",J26=0,J26="0"),J26,IF(OR(K26=1,K26="1",K26=0,K26="0"),K26,"NA"))) -> 1 | Q26: =IF(OR(L26=1,L26="1",L26=0,L26="0"),L26,IF(OR(M26=1,M26="1",M26=0,M26="0"),M26,IF(OR(N26=1,N26="1",N26=0,N26="0"),N26,"NA"))) -> 0 | R26: =AND(ROUND(P26,0)=1, ROUND(Q26,0)=0) -> TRUE
A27: 25 | B27: ADD | C27: tract_0028 | D27: D2_C2 | E27: 2.1868835 | F27: 41.413052 | G27: https://www.google.com/maps/@?api=1&map_action=pano&viewpoint=41.4130517909949,2.18688350279505 | H27: =HYPERLINK("https://www.google.com/maps/@?api=1&map_action=pano&viewpoint=41.4130517909949,2.18688350279505","Open GSV") -> Open GSV | I27: 1 | L27: 0 | P27: =IF(OR(I27=1,I27="1",I27=0,I27="0"),I27,IF(OR(J27=1,J27="1",J27=0,J27="0"),J27,IF(OR(K27=1,K27="1",K27=0,K27="0"),K27,"NA"))) -> 1 | Q27: =IF(OR(L27=1,L27="1",L27=0,L27="0"),L27,IF(OR(M27=1,M27="1",M27=0,M27="0"),M27,IF(OR(N27=1,N27="1",N27=0,N27="0"),N27,"NA"))) -> 0 | R27: =AND(ROUND(P27,0)=1, ROUND(Q27,0)=0) -> TRUE
A28: 26 | B28: ADD | C28: tract_0028 | D28: D2_C2 | E28: 2.1863076 | F28: 41.414041 | G28: https://www.google.com/maps/@?api=1&map_action=pano&viewpoint=41.4140408624214,2.18630763816643 | H28: =HYPERLINK("https://www.google.com/maps/@?api=1&map_action=pano&viewpoint=41.4140408624214,2.18630763816643","Open GSV") -> Open GSV | I28: 1 | L28: 0 | O28: peg moved 2023, 2015 lane with roadpaint indicating bike presence? | P28: =IF(OR(I28=1,I28="1",I28=0,I28="0"),I28,IF(OR(J28=1,J28="1",J28=0,J28="0"),J28,IF(OR(K28=1,K28="1",K28=0,K28="0"),K28,"NA"))) -> 1 | Q28: =IF(OR(L28=1,L28="1",L28=0,L28="0"),L28,IF(OR(M28=1,M28="1",M28=0,M28="0"),M28,IF(OR(N28=1,N28="1",N28=0,N28="0"),N28,"NA"))) -> 0 | R28: =AND(ROUND(P28,0)=1, ROUND(Q28,0)=0) -> TRUE
A29: 27 | B29: ADD | C29: tract_0030 | D29: D2_C2 | E29: 2.136257 | F29: 41.385981 | G29: https://www.google.com/maps/@?api=1&map_action=pano&viewpoint=41.3859805190524,2.13625700853397 | H29: =HYPERLINK("https://www.google.com/maps/@?api=1&map_action=pano&viewpoint=41.3859805190524,2.13625700853397","Open GSV") -> Open GSV | I29: NA | J29: NA | K29: 1 | L29: 0 | P29: =IF(OR(I29=1,I29="1",I29=0,I29="0"),I29,IF(OR(J29=1,J29="1",J29=0,J29="0"),J29,IF(OR(K29=1,K29="1",K29=0,K29="0"),K29,"NA"))) -> 1 | Q29: =IF(OR(L29=1,L29="1",L29=0,L29="0"),L29,IF(OR(M29=1,M29="1",M29=0,M29="0"),M29,IF(OR(N29=1,N29="1",N29=0,N29="0"),N29,"NA"))) -> 0 | R29: =AND(ROUND(P29,0)=1, ROUND(Q29,0)=0) -> TRUE
A30: 28 | B30: ADD | C30: tract_0030 | D30: D2_C2 | E30: 2.1385586 | F30: 41.385297 | G30: https://www.google.com/maps/@?api=1&map_action=pano&viewpoint=41.3852971271454,2.13855858286425 | H30: =HYPERLINK("https://www.google.com/maps/@?api=1&map_action=pano&viewpoint=41.3852971271454,2.13855858286425","Open GSV") -> Open GSV | I30: NA | J30: NA | K30: 1 | L30: 0 | O30: 2015 lane with road paint indicating bike rpesence? | P30: =IF(OR(I30=1,I30="1",I30=0,I30="0"),I30,IF(OR(J30=1,J30="1",J30=0,J30="0"),J30,IF(OR(K30=1,K30="1",K30=0,K30="0"),K30,"NA"))) -> 1 | Q30: =IF(OR(L30=1,L30="1",L30=0,L30="0"),L30,IF(OR(M30=1,M30="1",M30=0,M30="0"),M30,IF(OR(N30=1,N30="1",N30=0,N30="0"),N30,"NA"))) -> 0 | R30: =AND(ROUND(P30,0)=1, ROUND(Q30,0)=0) -> TRUE
A31: 29 | B31: ADD | C31: tract_0031 | D31: D2_C3 | E31: 2.1864299 | F31: 41.391188 | G31: https://www.google.com/maps/@?api=1&map_action=pano&viewpoint=41.3911878676426,2.18642991571189 | H31: =HYPERLINK("https://www.google.com/maps/@?api=1&map_action=pano&viewpoint=41.3911878676426,2.18642991571189","Open GSV") -> Open GSV | I31: 1 | L31: 0 | O31: peg moved both | P31: =IF(OR(I31=1,I31="1",I31=0,I31="0"),I31,IF(OR(J31=1,J31="1",J31=0,J31="0"),J31,IF(OR(K31=1,K31="1",K31=0,K31="0"),K31,"NA"))) -> 1 | Q31: =IF(OR(L31=1,L31="1",L31=0,L31="0"),L31,IF(OR(M31=1,M31="1",M31=0,M31="0"),M31,IF(OR(N31=1,N31="1",N31=0,N31="0"),N31,"NA"))) -> 0 | R31: =AND(ROUND(P31,0)=1, ROUND(Q31,0)=0) -> TRUE
A32: 30 | B32: ADD | C32: tract_0031 | D32: D2_C3 | E32: 2.185338 | F32: 41.390375 | G32: https://www.google.com/maps/@?api=1&map_action=pano&viewpoint=41.3903749358271,2.18533799661021 | H32: =HYPERLINK("https://www.google.com/maps/@?api=1&map_action=pano&viewpoint=41.3903749358271,2.18533799661021","Open GSV") -> Open GSV | I32: 1 | L32: 0 | O32: peg moved 2023. | P32: =IF(OR(I32=1,I32="1",I32=0,I32="0"),I32,IF(OR(J32=1,J32="1",J32=0,J32="0"),J32,IF(OR(K32=1,K32="1",K32=0,K32="0"),K32,"NA"))) -> 1 | Q32: =IF(OR(L32=1,L32="1",L32=0,L32="0"),L32,IF(OR(M32=1,M32="1",M32=0,M32="0"),M32,IF(OR(N32=1,N32="1",N32=0,N32="0"),N32,"NA"))) -> 0 | R32: =AND(ROUND(P32,0)=1, ROUND(Q32,0)=0) -> TRUE
A33: 31 | B33: ADD | C33: tract_0035 | D33: D2_C3 | E33: 2.1589756 | F33: 41.382643 | G33: https://www.google.com/maps/@?api=1&map_action=pano&viewpoint=41.3826431790481,2.15897555292766 | H33: =HYPERLINK("https://www.google.com/maps/@?api=1&map_action=pano&viewpoint=41.3826431790481,2.15897555292766","Open GSV") -> Open GSV | I33: 1 | L33: NA | M33: 1 | O33: Paint on sidewalk indicates bike lane 2014 -> FALSE ADD -> REALIGN | P33: =IF(OR(I33=1,I33="1",I33=0,I33="0"),I33,IF(OR(J33=1,J33="1",J33=0,J33="0"),J33,IF(OR(K33=1,K33="1",K33=0,K33="0"),K33,"NA"))) -> 1 | Q33: =IF(OR(L33=1,L33="1",L33=0,L33="0"),L33,IF(OR(M33=1,M33="1",M33=0,M33="0"),M33,IF(OR(N33=1,N33="1",N33=0,N33="0"),N33,"NA"))) -> 1 | R33: =AND(ROUND(P33,0)=1, ROUND(Q33,0)=0) -> FALSE
A34: 32 | B34: ADD | C34: tract_0036 | D34: D2_C3 | E34: 2.153705 | F34: 41.398118 | G34: https://www.google.com/maps/@?api=1&map_action=pano&viewpoint=41.3981184632183,2.15370501205099 | H34: =HYPERLINK("https://www.google.com/maps/@?api=1&map_action=pano&viewpoint=41.3981184632183,2.15370501205099","Open GSV") -> Open GSV | I34: 1 | L34: 0 | P34: =IF(OR(I34=1,I34="1",I34=0,I34="0"),I34,IF(OR(J34=1,J34="1",J34=0,J34="0"),J34,IF(OR(K34=1,K34="1",K34=0,K34="0"),K34,"NA"))) -> 1 | Q34: =IF(OR(L34=1,L34="1",L34=0,L34="0"),L34,IF(OR(M34=1,M34="1",M34=0,M34="0"),M34,IF(OR(N34=1,N34="1",N34=0,N34="0"),N34,"NA"))) -> 0 | R34: =AND(ROUND(P34,0)=1, ROUND(Q34,0)=0) -> TRUE
A35: 33 | B35: ADD | C35: tract_0036 | D35: D2_C3 | E35: 2.1537502 | F35: 41.398133 | G35: https://www.google.com/maps/@?api=1&map_action=pano&viewpoint=41.3981332109611,2.1537501547691 | H35: =HYPERLINK("https://www.google.com/maps/@?api=1&map_action=pano&viewpoint=41.3981332109611,2.1537501547691","Open GSV") -> Open GSV | I35: 1 | L35: 0 | O35: Same point as before. | P35: =IF(OR(I35=1,I35="1",I35=0,I35="0"),I35,IF(OR(J35=1,J35="1",J35=0,J35="0"),J35,IF(OR(K35=1,K35="1",K35=0,K35="0"),K35,"NA"))) -> 1 | Q35: =IF(OR(L35=1,L35="1",L35=0,L35="0"),L35,IF(OR(M35=1,M35="1",M35=0,M35="0"),M35,IF(OR(N35=1,N35="1",N35=0,N35="0"),N35,"NA"))) -> 0 | R35: =AND(ROUND(P35,0)=1, ROUND(Q35,0)=0) -> TRUE
A36: 34 | B36: ADD | C36: tract_0041 | D36: D3_C1 | E36: 2.1240095 | F36: 41.375664 | G36: https://www.google.com/maps/@?api=1&map_action=pano&viewpoint=41.3756644128399,2.1240095291374 | H36: =HYPERLINK("https://www.google.com/maps/@?api=1&map_action=pano&viewpoint=41.3756644128399,2.1240095291374","Open GSV") -> Open GSV | I36: 1 | L36: 0 | P36: =IF(OR(I36=1,I36="1",I36=0,I36="0"),I36,IF(OR(J36=1,J36="1",J36=0,J36="0"),J36,IF(OR(K36=1,K36="1",K36=0,K36="0"),K36,"NA"))) -> 1 | Q36: =IF(OR(L36=1,L36="1",L36=0,L36="0"),L36,IF(OR(M36=1,M36="1",M36=0,M36="0"),M36,IF(OR(N36=1,N36="1",N36=0,N36="0"),N36,"NA"))) -> 0 | R36: =AND(ROUND(P36,0)=1, ROUND(Q36,0)=0) -> TRUE
A37: 35 | B37: ADD | C37: tract_0043 | D37: D3_C2 | E37: 2.130759 | F37: 41.375087 | G37: https://www.google.com/maps/@?api=1&map_action=pano&viewpoint=41.3750869481267,2.13075902951078 | H37: =HYPERLINK("https://www.google.com/maps/@?api=1&map_action=pano&viewpoint=41.3750869481267,2.13075902951078","Open GSV") -> Open GSV | I37: 1 | L37: 1 | O37: FALSE ADD --> No changes (always bike/walkside or never bike/walkside, according to near pedestrian crossing) | P37: =IF(OR(I37=1,I37="1",I37=0,I37="0"),I37,IF(OR(J37=1,J37="1",J37=0,J37="0"),J37,IF(OR(K37=1,K37="1",K37=0,K37="0"),K37,"NA"))) -> 1 | Q37: =IF(OR(L37=1,L37="1",L37=0,L37="0"),L37,IF(OR(M37=1,M37="1",M37=0,M37="0"),M37,IF(OR(N37=1,N37="1",N37=0,N37="0"),N37,"NA"))) -> 1 | R37: =AND(ROUND(P37,0)=1, ROUND(Q37,0)=0) -> FALSE
A38: 36 | B38: ADD | C38: tract_0043 | D38: D3_C2 | E38: 2.1311878 | F38: 41.37384 | G38: https://www.google.com/maps/@?api=1&map_action=pano&viewpoint=41.3738399462803,2.13118777902404 | H38: =HYPERLINK("https://www.google.com/maps/@?api=1&map_action=pano&viewpoint=41.3738399462803,2.13118777902404","Open GSV") -> Open GSV | I38: 1 | L38: 1 | O38: 2023 and 2024 underground, 2022 same point overground (no bikelane) / 2015 only underground if peg not moved before year switch (no bikeline either) -> FALSE ADD | P38: =IF(OR(I38=1,I38="1",I38=0,I38="0"),I38,IF(OR(J38=1,J38="1",J38=0,J38="0"),J38,IF(OR(K38=1,K38="1",K38=0,K38="0"),K38,"NA"))) -> 1 | Q38: =IF(OR(L38=1,L38="1",L38=0,L38="0"),L38,IF(OR(M38=1,M38="1",M38=0,M38="0"),M38,IF(OR(N38=1,N38="1",N38=0,N38="0"),N38,"NA"))) -> 1 | R38: =AND(ROUND(P38,0)=1, ROUND(Q38,0)=0) -> FALSE
A39: 37 | B39: ADD | C39: tract_0044 | D39: D3_C2 | E39: 2.1797608 | F39: 41.41188 | G39: https://www.google.com/maps/@?api=1&map_action=pano&viewpoint=41.4118804921771,2.17976081270431 | H39: =HYPERLINK("https://www.google.com/maps/@?api=1&map_action=pano&viewpoint=41.4118804921771,2.17976081270431","Open GSV") -> Open GSV | I39: NA | J39: NA | K39: 0 | L39: 0 | O39: FALSE ADD | P39: =IF(OR(I39=1,I39="1",I39=0,I39="0"),I39,IF(OR(J39=1,J39="1",J39=0,J39="0"),J39,IF(OR(K39=1,K39="1",K39=0,K39="0"),K39,"NA"))) -> 0 | Q39: =IF(OR(L39=1,L39="1",L39=0,L39="0"),L39,IF(OR(M39=1,M39="1",M39=0,M39="0"),M39,IF(OR(N39=1,N39="1",N39=0,N39="0"),N39,"NA"))) -> 0 | R39: =AND(ROUND(P39,0)=1, ROUND(Q39,0)=0) -> FALSE
A40: 38 | B40: ADD | C40: tract_0044 | D40: D3_C2 | E40: 2.1808908 | F40: 41.412745 | G40: https://www.google.com/maps/@?api=1&map_action=pano&viewpoint=41.4127447371871,2.180890772398 | H40: =HYPERLINK("https://www.google.com/maps/@?api=1&map_action=pano&viewpoint=41.4127447371871,2.180890772398","Open GSV") -> Open GSV | I40: NA | J40: NA | K40: 0 | L40: 0 | O40: Peg moved 2023 (roadworks - may be bike lane works but cannot confirm) -> FALSE ADD | P40: =IF(OR(I40=1,I40="1",I40=0,I40="0"),I40,IF(OR(J40=1,J40="1",J40=0,J40="0"),J40,IF(OR(K40=1,K40="1",K40=0,K40="0"),K40,"NA"))) -> 0 | Q40: =IF(OR(L40=1,L40="1",L40=0,L40="0"),L40,IF(OR(M40=1,M40="1",M40=0,M40="0"),M40,IF(OR(N40=1,N40="1",N40=0,N40="0"),N40,"NA"))) -> 0 | R40: =AND(ROUND(P40,0)=1, ROUND(Q40,0)=0) -> FALSE
...

Sheet REMOVE_evt
I1: 2023 | L1: 2015
A2: id | B2: class | C2: tract_id | D2: stratum | E2: lon | F2: lat | G2: gsv_link | H2: GSV | I2: present_2023 | J2: present_2024 | K2: present_2022 | L2: present_2015 | M2: present_2014 | N2: present_2016 | O2: notes | P2: present_followup | Q2: present_baseline | R2: Match
A3: 1 | B3: REMOVE | C3: tract_0001 | D3: D1_C1 | E3: 2.1040062 | F3: 41.38494 | G3: https://www.google.com/maps/@?api=1&map_action=pano&viewpoint=41.3849403989724,2.10400617396064 | H3: =HYPERLINK("https://www.google.com/maps/@?api=1&map_action=pano&viewpoint=41.3849403989724,2.10400617396064","Open GSV") -> Open GSV | I3: 0 | L3: NA | M3: 0 | O3: Peg moved both | P3: =IF(OR(I3=1,I3="1",I3=0,I3="0"),I3,IF(OR(J3=1,J3="1",J3=0,J3="0"),J3,IF(OR(K3=1,K3="1",K3=0,K3="0"),K3,"NA"))) -> 0 | Q3: =IF(OR(L3=1,L3="1",L3=0,L3="0"),L3,IF(OR(M3=1,M3="1",M3=0,M3="0"),M3,IF(OR(N3=1,N3="1",N3=0,N3="0"),N3,"NA"))) -> 0 | R3: =AND(ROUND(P3,0)=0, ROUND(Q3,0)=1) -> FALSE
A4: 2 | B4: REMOVE | C4: tract_0008 | D4: D1_C2 | E4: 2.2007798 | F4: 41.42019 | G4: https://www.google.com/maps/@?api=1&map_action=pano&viewpoint=41.4201900660698,2.20077984083242 | H4: =HYPERLINK("https://www.google.com/maps/@?api=1&map_action=pano&viewpoint=41.4201900660698,2.20077984083242","Open GSV") -> Open GSV | I4: NA | J4: 1 | L4: 1 | P4: =IF(OR(I4=1,I4="1",I4=0,I4="0"),I4,IF(OR(J4=1,J4="1",J4=0,J4="0"),J4,IF(OR(K4=1,K4="1",K4=0,K4="0"),K4,"NA"))) -> 1 | Q4: =IF(OR(L4=1,L4="1",L4=0,L4="0"),L4,IF(OR(M4=1,M4="1",M4=0,M4="0"),M4,IF(OR(N4=1,N4="1",N4=0,N4="0"),N4,"NA"))) -> 1 | R4: =AND(ROUND(P4,0)=0, ROUND(Q4,0)=1) -> FALSE
A5: 3 | B5: REMOVE | C5: tract_0017 | D5: D1_C3 | E5: 2.1483858 | F5: 41.375372 | G5: https://www.google.com/maps/@?api=1&map_action=pano&viewpoint=41.3753719135312,2.14838582462673 | H5: =HYPERLINK("https://www.google.com/maps/@?api=1&map_action=pano&viewpoint=41.3753719135312,2.14838582462673","Open GSV") -> Open GSV | I5: 0 | L5: NA | M5: 0 | O5: Peg moved both | P5: =IF(OR(I5=1,I5="1",I5=0,I5="0"),I5,IF(OR(J5=1,J5="1",J5=0,J5="0"),J5,IF(OR(K5=1,K5="1",K5=0,K5="0"),K5,"NA"))) -> 0 | Q5: =IF(OR(L5=1,L5="1",L5=0,L5="0"),L5,IF(OR(M5=1,M5="1",M5=0,M5="0"),M5,IF(OR(N5=1,N5="1",N5=0,N5="0"),N5,"NA"))) -> 0 | R5: =AND(ROUND(P5,0)=0, ROUND(Q5,0)=1) -> FALSE
A6: 4 | B6: REMOVE | C6: tract_0020 | D6: D2_C1 | E6: 2.1797919 | F6: 41.432573 | G6: https://www.google.com/maps/@?api=1&map_action=pano&viewpoint=41.4325734990105,2.17979187635586 | H6: =HYPERLINK("https://www.google.com/maps/@?api=1&map_action=pano&viewpoint=41.4325734990105,2.17979187635586","Open GSV") -> Open GSV | I6: 0 | L6: NA | M6: 0 | P6: =IF(OR(I6=1,I6="1",I6=0,I6="0"),I6,IF(OR(J6=1,J6="1",J6=0,J6="0"),J6,IF(OR(K6=1,K6="1",K6=0,K6="0"),K6,"NA"))) -> 0 | Q6: =IF(OR(L6=1,L6="1",L6=0,L6="0"),L6,IF(OR(M6=1,M6="1",M6=0,M6="0"),M6,IF(OR(N6=1,N6="1",N6=0,N6="0"),N6,"NA"))) -> 0 | R6: =AND(ROUND(P6,0)=0, ROUND(Q6,0)=1) -> FALSE
A7: 5 | B7: REMOVE | C7: tract_0023 | D7: D2_C1 | E7: 2.1744355 | F7: 41.43024 | G7: https://www.google.com/maps/@?api=1&map_action=pano&viewpoint=41.4302401188698,2.17443553665477 | H7: =HYPERLINK("https://www.google.com/maps/@?api=1&map_action=pano&viewpoint=41.4302401188698,2.17443553665477","Open GSV") -> Open GSV | I7: 0 | L7: NA | M7: 0 | P7: =IF(OR(I7=1,I7="1",I7=0,I7="0"),I7,IF(OR(J7=1,J7="1",J7=0,J7="0"),J7,IF(OR(K7=1,K7="1",K7=0,K7="0"),K7,"NA"))) -> 0 | Q7: =IF(OR(L7=1,L7="1",L7=0,L7="0"),L7,IF(OR(M7=1,M7="1",M7=0,M7="0"),M7,IF(OR(N7=1,N7="1",N7=0,N7="0"),N7,"NA"))) -> 0 | R7: =AND(ROUND(P7,0)=0, ROUND(Q7,0)=1) -> FALSE
A8: 6 | B8: REMOVE | C8: tract_0035 | D8: D2_C3 | E8: 2.1568127 | F8: 41.38434 | G8: https://www.google.com/maps/@?api=1&map_action=pano&viewpoint=41.3843400360326,2.15681272246317 | H8: =HYPERLINK("https://www.google.com/maps/@?api=1&map_action=pano&viewpoint=41.3843400360326,2.15681272246317","Open GSV") -> Open GSV | I8: 0 | L8: 1 | O8: Peg moved both | P8: =IF(OR(I8=1,I8="1",I8=0,I8="0"),I8,IF(OR(J8=1,J8="1",J8=0,J8="0"),J8,IF(OR(K8=1,K8="1",K8=0,K8="0"),K8,"NA"))) -> 0 | Q8: =IF(OR(L8=1,L8="1",L8=0,L8="0"),L8,IF(OR(M8=1,M8="1",M8=0,M8="0"),M8,IF(OR(N8=1,N8="1",N8=0,N8="0"),N8,"NA"))) -> 1 | R8: =AND(ROUND(P8,0)=0, ROUND(Q8,0)=1) -> TRUE
A9: 7 | B9: REMOVE | C9: tract_0035 | D9: D2_C3 | E9: 2.157262 | F9: 41.38328 | G9: https://www.google.com/maps/@?api=1&map_action=pano&viewpoint=41.3832798659396,2.15726201275132 | H9: =HYPERLINK("https://www.google.com/maps/@?api=1&map_action=pano&viewpoint=41.3832798659396,2.15726201275132","Open GSV") -> Open GSV | I9: NA | J9: NA | K9: NA | L9: NA | M9: NA | N9: NA | O9: Peg moved both; realignment 24 | P9: =IF(OR(I9=1,I9="1",I9=0,I9="0"),I9,IF(OR(J9=1,J9="1",J9=0,J9="0"),J9,IF(OR(K9=1,K9="1",K9=0,K9="0"),K9,"NA"))) -> NA | Q9: =IF(OR(L9=1,L9="1",L9=0,L9="0"),L9,IF(OR(M9=1,M9="1",M9=0,M9="0"),M9,IF(OR(N9=1,N9="1",N9=0,N9="0"),N9,"NA"))) -> NA | R9: =AND(ROUND(P9,0)=0, ROUND(Q9,0)=1) -> #VALUE!
A10: 8 | B10: REMOVE | C10: tract_0050 | D10: D3_C3 | E10: 2.1521384 | F10: 41.38094 | G10: https://www.google.com/maps/@?api=1&map_action=pano&viewpoint=41.3809395290626,2.15213844443264 | H10: =HYPERLINK("https://www.google.com/maps/@?api=1&map_action=pano&viewpoint=41.3809395290626,2.15213844443264","Open GSV") -> Open GSV | I10: 0 | L10: 1 | O10: road works 23 | P10: =IF(OR(I10=1,I10="1",I10=0,I10="0"),I10,IF(OR(J10=1,J10="1",J10=0,J10="0"),J10,IF(OR(K10=1,K10="1",K10=0,K10="0"),K10,"NA"))) -> 0 | Q10: =IF(OR(L10=1,L10="1",L10=0,L10="0"),L10,IF(OR(M10=1,M10="1",M10=0,M10="0"),M10,IF(OR(N10=1,N10="1",N10=0,N10="0"),N10,"NA"))) -> 1 | R10: =AND(ROUND(P10,0)=0, ROUND(Q10,0)=1) -> TRUE
R11: =COUNTIFS(R3:R10,1) -> 2 | S11: =COUNTIFS(R3:R10,1) / (COUNTIFS(R3:R10,1) + COUNTIFS(R3:R10,0)) -> 0.28571429

Sheet REMOVE_vgp
I1: 2023 | L1: 2015
A2: id | B2: class | C2: tract_id | D2: stratum | E2: lon | F2: lat | G2: gsv_link | H2: GSV | I2: present_2023 | J2: present_2024 | K2: present_2022 | L2: present_2015 | M2: present_2014 | N2: present_2016 | O2: notes | P2: present_followup | Q2: present_baseline | R2: Match
